<?xml version="1.0" ?>
<!-- =================================================================================== -->
<!-- |       This is the  WORKING example. The only difference is at line 183          | -->
<!-- =================================================================================== -->
<robot name="amiga">
  <link name="dummy_link"/>
  <joint name="dummy_joint" type="fixed">
    <parent link="dummy_link"/>
    <child link="base_link"/>
    <origin rpy="0 0 0" xyz="0 0 0"/>
    <axis xyz="0 0 0"/>
  </joint>
  <link name="base_link">
    <inertial>
      <origin rpy="0 0 0" xyz="-0.013975 0.051448 3.6862E-05"/>
      <mass value="110.78"/>
      <inertia ixx="0.50372" ixy="0.034645" ixz="0.00011003" iyy="3.112" iyz="0.00034085" izz="3.1694"/>
    </inertial>
    <visual>
      <origin rpy="0 0 0" xyz="0 0 0"/>
      <geometry>
        <mesh filename="package://arnie_description/robots/meshes/base_link.STL"/>
      </geometry>
      <material name="">
        <color rgba="1 1 1 1"/>
      </material>
    </visual>
    <collision>
      <origin rpy="0 0 0" xyz="0 0 0"/>
      <geometry>
        <mesh filename="package://arnie_description/robots/meshes/base_link.STL"/>
      </geometry>
    </collision>
  </link>
  <link name="drive_wheel_right">
    <inertial>
      <origin rpy="0 0 0" xyz="-3.4907E-12 0.028895 1.236E-14"/>
      <mass value="3.9607"/>
      <inertia ixx="0.028179" ixy="3.3797E-15" ixz="-1.2302E-12" iyy="0.054226" iyz="-1.2741E-17" izz="0.028179"/>
    </inertial>
    <visual>
      <origin rpy="0 0 0" xyz="0 0 0"/>
      <geometry>
        <mesh filename="package://arnie_description/robots/meshes/drive_wheel_right.STL"/>
      </geometry>
      <material name="">
        <color rgba="0.29804 0.29804 0.29804 1"/>
      </material>
    </visual>
    <collision>
      <origin rpy="0 0 0" xyz="0 0 0"/>
      <geometry>
        <mesh filename="package://arnie_description/robots/meshes/drive_wheel_right.STL"/>
      </geometry>
    </collision>
  </link>
  <joint name="base_drive_wheel_right" type="continuous">
    <origin rpy="0 -0.8593 0" xyz="0 0.1995 0"/>
    <parent link="base_link"/>
    <child link="drive_wheel_right"/>
    <axis xyz="0 1 0"/>
  </joint>
  <link name="drive_wheel_left">
    <inertial>
      <origin rpy="0 0 0" xyz="-3.4906E-12 0.028895 1.2374E-14"/>
      <mass value="3.9607"/>
      <inertia ixx="0.028179" ixy="3.3837E-15" ixz="-1.2302E-12" iyy="0.054226" iyz="-1.3611E-17" izz="0.028179"/>
    </inertial>
    <visual>
      <origin rpy="0 0 0" xyz="0 0 0"/>
      <geometry>
        <mesh filename="package://arnie_description/robots/meshes/drive_wheel_left.STL"/>
      </geometry>
      <material name="">
        <color rgba="0.29804 0.29804 0.29804 1"/>
      </material>
    </visual>
    <collision>
      <origin rpy="0 0 0" xyz="0 0 0"/>
      <geometry>
        <mesh filename="package://arnie_description/robots/meshes/drive_wheel_left.STL"/>
      </geometry>
    </collision>
  </link>
  <joint name="base_drive_wheel_left" type="continuous">
    <origin rpy="3.1416 -0.00012658 0" xyz="0 -0.1995 0"/>
    <parent link="base_link"/>
    <child link="drive_wheel_left"/>
    <axis xyz="0 1 0"/>
  </joint>
  <link name="castor_front_left">
    <inertial>
      <origin rpy="0 0 0" xyz="0.010525 -0.0097266 7.7108E-08"/>
      <mass value="0.20821"/>
      <inertia ixx="0.00055537" ixy="8.8662E-05" ixz="8.9051E-11" iyy="0.00024751" iyz="1.6993E-09" izz="0.00042332"/>
    </inertial>
    <visual>
      <origin rpy="0 0 0" xyz="0 0 0"/>
      <geometry>
        <mesh filename="package://arnie_description/robots/meshes/castor_front_left.STL"/>
      </geometry>
      <material name="">
        <color rgba="0.19216 0.20392 0.20392 1"/>
      </material>
    </visual>
    <collision>
      <origin rpy="0 0 0" xyz="0 0 0"/>
      <geometry>
        <mesh filename="package://arnie_description/robots/meshes/castor_front_left.STL"/>
      </geometry>
    </collision>
  </link>
  <joint name="base_to_castor_front_left" type="continuous">
    <origin rpy="1.5708 0 3.1416" xyz="-0.38799 -0.17127 0"/>
    <parent link="base_link"/>
    <child link="castor_front_left"/>
    <axis xyz="0 1 0"/>
  </joint>
  <link name="front_wheel_left">
    <inertial>
      <origin rpy="0 0 0" xyz="5.5511E-17 -4.3723E-13 1.5266E-16"/>
      <mass value="1.1217"/>
      <inertia ixx="0.0024847" ixy="2.8893E-15" ixz="3.8142E-20" iyy="0.0045217" iyz="-3.3191E-19" izz="0.0024847"/>
    </inertial>
    <visual>
      <origin rpy="0 0 0" xyz="0 0 0"/>
      <geometry>
        <mesh filename="package://arnie_description/robots/meshes/front_wheel_left.STL"/>
      </geometry>
      <material name="">
        <color rgba="0.89412 0.89412 0.89412 1"/>
      </material>
    </visual>
    <collision>
      <origin rpy="0 0 0" xyz="0 0 0"/>
      <geometry>
        <mesh filename="package://arnie_description/robots/meshes/front_wheel_left.STL"/>
      </geometry>
    </collision>
  </link>
  <joint name="castor_to_front_wheel_left" type="continuous">
    <origin rpy="1.5708 0 3.1416" xyz="0.026228 -0.0725 0"/>
    <parent link="castor_front_left"/>
    <child link="front_wheel_left"/>
    <axis xyz="0 1 0"/>
  </joint>
  <link name="castor_front_right">
    <inertial>
      <origin rpy="0 0 0" xyz="0.010525 -0.0097266 7.7108E-08"/>
      <mass value="0.59378"/>
      <inertia ixx="0.0015838" ixy="0.00025285" ixz="2.5396E-10" iyy="0.00070588" iyz="4.8462E-09" izz="0.0012073"/>
    </inertial>
    <visual>
      <origin rpy="0 0 0" xyz="0 0 0"/>
      <geometry>
        <mesh filename="package://arnie_description/robots/meshes/castor_front_right.STL"/>
      </geometry>
      <material name="">
        <color rgba="0.058824 0.058824 0.058824 1"/>
      </material>
    </visual>
    <collision>
      <origin rpy="0 0 0" xyz="0 0 0"/>
      <geometry>
        <mesh filename="package://arnie_description/robots/meshes/castor_front_right.STL"/>
      </geometry>
    </collision>
  </link>
  <joint name="base_to_castor_front_right" type="continuous">
    <origin rpy="1.5708 0 3.1416" xyz="-0.38799 0.17127 0"/>
    <parent link="base_link"/>
    <child link="castor_front_right"/>
    <axis xyz="0 1 0"/>
  </joint>


  <link name="front_wheel_right">
    <inertial>
      <origin rpy="0 0 0" xyz="-5.5511E-17 -4.3723E-13 1.9429E-16"/>
      <mass value="1.1217"/>

      <!-- This line works right now. To make the bug happen, use not_working.urdf (or simply replace ixz="3.8142E-20" by ixz="1.0955E-20") -->
      <inertia ixx="0.0024847" ixy="8.549E-18" ixz="3.8142E-20" iyy="0.0045217" iyz="-3.8877E-20" izz="0.0024847"/>

    </inertial>
    <visual>
      <origin rpy="0 0 0" xyz="0 0 0"/>
      <geometry>
        <mesh filename="package://arnie_description/robots/meshes/front_wheel_right.STL"/>
      </geometry>
      <material name="">
        <color rgba="0.89412 0.89412 0.89412 1"/>
      </material>
    </visual>
    <collision>
      <origin rpy="0 0 0" xyz="0 0 0"/>
      <geometry>
        <mesh filename="package://arnie_description/robots/meshes/front_wheel_right.STL"/>
      </geometry>
    </collision>
  </link>
  <joint name="castor_to_front_wheel_right" type="continuous">
    <origin rpy="1.5708 0 3.1416" xyz="0.026228 -0.0725 0"/>
    <parent link="castor_front_right"/>
    <child link="front_wheel_right"/>
    <axis xyz="0 1 0"/>
  </joint>
</robot>
